# Обработка исключений в C++

## Обработка ошибок и непредвиденных ситуаций
- В процессе работы программы возможно возникновение непредвиденных ситуаций
  - Нехватка памяти и других системных ресурсов
  - Ошибки ввода-вывода
  - Некорректные данные, поступившие от пользователя
  - Нарушение целостности данных (поврежден файл с данными)
  - Некорректные параметры функций
- Хорошо спроектированная программа должна уметь обнаруживать, сигнализировать и обрабатывать данные ситуации
  - Сообщить об ошибке пользователю
  - Попытаться исправить ошибки
  - При невозможности дальнейшей работы – сохранить данные и завершить работу

## Обнаружение ошибочных ситуаций
- Проверяйте данные поступающие из внешних источников на корректность
  - Файлы, введенные пользователем данные, сетевые пакеты и т.п.
- Осуществляйте проверку успешности вызовов функций используемого API
  - Функции ввода/вывода, выделения/освобождения ресурсов

## Способы обработки ошибок
- Проигнорировать ошибку, оставив программу в неопределенном состоянии
  - Самый худший вариант – никогда так не делайте!
- Вывод сообщения об ошибке и аварийное завершение работы программы
  - Немногим лучше предыдущего
- Поместить код ошибки в глобальную переменную
  - Проблемы с многопоточными приложениями
- Предусмотреть специальное значение функции, сигнализирующее об ошибке
  - А что, если ошибка произошла в конструкторе класса или в перегруженной операции?
- Вызвать функцию-обработчик ошибки
  - Часто необходимо передавать контекст возникновения ошибки
  - Необходимо восстанавливать нормальное выполнение
- Воспользоваться механизмом исключений языка C++

### Возникновение ошибки в конструкторе
```c++
class Rational {
public:
    Rational(int numerator = 0): m_numerator{numerator} { }

    Rational(int numerator, int denominator)
        : m_numerator{numerator}, m_denominator{denominator} {
        if (m_denominator == 0) {
            // Что делать?
        }
        /*...*/
    }
    int GetNumerator() const { return m_numerator; }
    int GetDenominator() const { return m_denominator; }
private:
    int m_numerator = 0;
    int m_denominator = 1;
};
```

### Ошибки в перегруженных операциях
```c++
Rational operator/(Rational lhs, Rational rhs)
{
    if (rhs.GetNumerator() == 0)
    {
        // Что делать?
    }
}
```

```c++
class Rational {
public:
    bool IsValid() const { return m_denominator != 0; }
private:
    int m_numerator = 0;
    int m_denominator = 1;
};


Rational operator/(Rational lhs, Rational rhs) {
    if (!lhs.IsValid() || !rhs.IsValid()) { return { 0, 0 }; }

    return { lhs.GetNumerator() * rhs.GetDenominator(),
             rhs.GetNumerator() * lhs.GetDenominator() };
}

int main() {
    Rational a, b;
    /* ... */
    Rational c = a / b;
    if (c.IsValid()) {
        /* ... */
    }
}
```

## Механизм исключений
- Встроенное в язык C++ средство для обработки внештатных ситуаций во время выполнения программы
- Исключения позволяют программе обработать внештатную ситуацию на более высоком уровне, на котором возможно восстановить нормальную работу программы
- Обработка исключений осуществляется кодом вне обычного потока выполнения

### Когда использовать исключения
- Состояние программы в момент ошибки должно быть восстановимо
- Ошибку нужно обработать на более высоком уровне
  - Например, функция сортировки не должна знать, что делать при нехватке памяти, а вот использующая её программа – может обработать эту ситуацию

### Когда не использовать исключения
- Ошибка может быть обработана локально
  - Обрабатываем локально и работаем дальше
- Восстановить работу программы нельзя

## try-блок
```c++
try
{
    /* Код, который может выбросить исключение */
}
catch (Тип перехватываемого исключения)
{
    /* Код, обрабатывающий исключение */
}
catch (Тип перехватываемого исключения)
{
    /* Код, обрабатывающий исключение */
}
catch (...)
{
    /* Код, обрабатывающий все прочие исключения */
}
```

## throw-выражение
- Синтаксис:
  - throw [выражение]
  - throw
  - Выражение может быть любого типа (кроме void)
- Семантика
  - Создается объект исключительной ситуации на основе переданного выражения (копирование либо перемещение)
  - Дальнейшее выполнение программы прерывается, происходит поиск ближайшего подходящего обработчика в блоке try-catch
    - Если подходящий обработчик найден, то происходит раскрутка стека (stack unwinding), при которой разрушаются все автоматические объекты, созданные между началом соответствующего блока try
    - Если обработчик не найден, происходит завершение работы программы

### Классы в качестве объектов исключений
- Класс может хранить подробную информация об исключительной ситуации
- Обработчик исключений родительского класса может перехватывать исключения публичных наследников этого класса
```c++
try {
throw FileError();
} catch (Error const& e) {
// Поймает Error, FileError и OutOfMemory
}
```

```c++
class Rational {
public:
    Rational(int numerator, int denominator)
        : m_numerator{ numerator }, m_denominator{ denominator } {
        if (m_denominator == 0) {
            throw std::invalid_argument("Denominator must be nonzero");
        }
        …
    }
};

Rational operator/(Rational lhs, Rational rhs) {
    if (rhs.GetDenominator() == 0) {
        throw std::invalid_argument("Division by zero");
    }
    return { lhs.GetNumerator() * rhs.GetDenominator(), rhs.GetNumerator() * lhs.GetDenominator() };
}

int main() {
    Rational a, b;
    try {
        Rational c = a / b;
    }
    catch(const std::exception& e) {
        std::cerr << e.what() << '\n';
    }
}
```

### Класс для отслеживания времени жизни
```c++
class Logger {
public:
    Logger(std::string name)
        : m_name{ std::move(name) } {
        std::cout << "Logger " << m_name << " was created\n";
    }
    Logger(const Logger& other) : m_name{ other.m_name } {
        std::cout << "Logger " << m_name << " was copied\n";
    }

    Logger& operator=(const Logger&) = delete; // No assignment

    ~Logger() {
        std::cout << "Logger " << m_name << " was destroyed\n";
    }

private:
    std::string m_name;
};
```

### Штатное выполнение
```c++
void Bar() {
    Logger logger{ "Bar" };
}

void Foo() {
    Logger logger{ "Foo" };
    Bar();
}

int main() {
    Logger logger{ "main" };
    Foo();
}
```

Logger main was created
Logger Foo was created
Logger Bar was created
Logger Bar was destroyed
Logger Foo was destroyed
Logger main was destroyed

### Аварийное завершение программы
```c++
void Bar() {
    Logger logger{ "Bar" };
    abort();
}

void Foo() {
    Logger logger{ "Foo" };
    Bar();
}

int main() {
    Logger logger{ "main" };
    Foo();
}
```

Logger main was created
Logger Foo was created
Logger Bar was created

### Выбрасывание исключения
```c++
void Bar() {
    Logger logger{ "Bar" };
    throw std::runtime_error("Error in Bar");
    std::cout << "Exit from bar";
}

void Foo() {
    Logger logger{ "Foo" };
    Bar();
}

int main() {
    try {
        Logger logger{ "main" };
        Foo();
        std::cout << "OK" << std::endl;
    } catch (const std::exception& e) {
        std::cout << "Caught " << e.what() << std::endl;
    }
}
```

Logger main was created
Logger Foo was created
Logger Bar was created
Logger Bar was destroyed
Logger Foo was destroyed
Logger main was destroyed
Caught Error in Bar

## Выбрасывание и перехват исключений в C++
- Исключения всегда выбрасываются «по значению»
  - У классов исключений должен быть доступен конструктор копирования и деструктор
- Перехват исключений должен происходить по ссылке
  - В случае перехвата базового класса исключения по значению может произойти «урезание» информации об исключении класса-наследника

### Срезка
```c++
class Base {
   …
   virtual void PrintInfo() const;
};

class Derived : public Base {
    …
    void PrintInfo() const override;
};

void PrintInfo(Base base) {
    base.PrintInfo();
}

int main() {
    Derived d;
    PrintInfo(d); // PrintInfo(static_cast<Base&>(d));
}
```

```c++
class Base {
public:
    Base(std::string const& message) 
        : m_message(message) { }
    std::string GetMessage() const {
        return m_message;
    }
    virtual void PrintInfo() const {
        std::cout << "Base exception: "
                  << m_message << "\n";
    }
    virtual ~Base() = default;
private:
    std::string m_message;
};

class Derived : public Base {
public:
    Derived(std::string const& message)
        : CBase(message) { }
    void PrintInfo() const override {
        std::cout << "Derived exception: "
                  << GetMessage() << "\n";
    }
};

int main() {
    try {
        Derived error("SomeInfo");
        error.PrintInfo();
        throw error;
    }
    // Срезка
    catch (Base e) {
        e.PrintInfo();
    }
}
```

Output:
Derived exception: SomeInfo
Base exception: SomeInfo

```c++
class Base {
public:
    Base(const std::string& message) 
        : m_message(message) { }
    std::string GetMessage() const {
        return m_message;
    }
    virtual void PrintInfo() const {
        std::cout << "Base exception: "
                  << m_message << "\n";
    }
    virtual ~Base() = default;
private:
    std::string m_message;
};

class Derived : public Base {
public:
    Derived(std::string const& message)
        : CBase(message) { }
    void PrintInfo() const override {
        std::cout << "Derived exception: "
                  << GetMessage() << "\n";
    }
};

int main() {
    try {
        Derived error("SomeInfo");
        error.PrintInfo();
        throw error;
    }
    // Теперь ок
    catch (const Base& e) {
        e.PrintInfo();
    }
}
```

Output:
Derived exception: SomeInfo
Derived exception: SomeInfo

### Перевыброс исключения
- Перехватив исключение в блоке catch можно перевыбросить его снова, чтобы оно было перехвачено внешним обработчиком
- Эта особенность идиоматична для C++, в котором классы – являются value-типами.
  - В языках типа Java, C#, где классы являются reference-типами, используется явное выбрасывание пойманного объекта
- Синтаксис:
  - throw;
- Пример:
```c++
try
{
...
}
catch(SomeError const& e)
{
//...
throw;
}
```

```c++
template <typename T>
class Vector {
public:
    Vector() = default;

    explicit Vector(size_t size)
            : data_(Allocate(size))
            , capacity_(size)
            , size_(size)
    {
        size_t i = 0;
        try {
            for (; i != size; ++i) {
                new (data_ + i) T();
            }
        } catch (...) {
            // В переменной i содержится количество созданных элементов.
            // Теперь их надо разрушить
            DestroyN(data_, i);
            // Освобождаем память, выделенную через Allocate
            Deallocate(data_);
            // Перевыбрасываем пойманное исключение, чтобы сообщить об ошибке создания объекта
            throw;
        }
    }
};
```

## Некоторые стандартные классы исключений
- exception – базовый класс для всех исключений, выбрасываемых кодом библиотеки
- logic_error – базовый класс для ошибок, которые можно было бы выявить до выполнения программы
- runtime_error – базовый класс ошибок, которые, как правило, можно выявить только во время работы программы
- bad_alloc – ошибка выделения памяти
- bad_cast – ошибка приведения типа
- bad_optional_access – попытка вызывать value() у пустого optional

### Преимущества использования исключений
- Реакция на исключение происходит всегда
  - Коды ошибок работают только тогда, когда их проверяют
- Возможность различной реакции на различные типы исключений
- Отделение кода обработки ошибок от кода, выполняющего «полезную» работу
- Объекты, выбрасываемые при исключении могут нести доп. информацию об исключительной ситуации
  - имя файла и номер строки, сообщение об ошибке, код системной ошибки и т.п.
- Исключение выбрасывается в одном месте, а обрабатывается на уровень выше

### Недостатки исключений
- При использовании исключений необходимо иметь представление о том, какие исключения могут быть выброшены в результате работы функции или метода класса
- Увеличение размеров машинного кода и некоторое снижение его быстродействия (особенно, если исключение выбросилось)
- Необходимость разработки кода, устойчивого к возникновению исключений

### Выброс исключения в конструкторе
- При выбросе исключения в теле конструктора или в списке инициализации процесс конструирования экземпляра класса прерывается и он считается не созданным
  - Деструктор для такого объекта вызван не будет
- Будут вызваны деструкторы для тех полей объекта, для которых успели выполниться конструкторы
  - Порядок вызова конструкторов полей класса совпадает с порядком их перечисления в  объявлении класса
  - Порядок вызова деструкторов – обратный порядку вызова конструкторов

## Методы и функции, не выбрасывающие исключений

### Спецификатор noexcept
- Указывает на то, может ли функция или метод выбросить исключение
- Синтаксис
  - noexcept(выражение)
    - Если значение выражения равно true, функция не выбрасывает исключений
  - noexcept – то же, что noexcept(true)
  - Выражение должно быть вычислимо во время компиляции

```c++
void MayThrow();
void MayThrowAsWell() noexcept(false);

void DoesNotThrow() noexcept;
void DoesNotThrowAsWell() noexcept(true);
```

### Что если noexcept-функция выбросит исключение?
- Если исключение не будет поймано внутри noexcept-функции, вызовется std::terminate и программа завершит свою работу
- noexcept-функции должны либо всегда завершаться успехом, либо использовать альтернативные способы сообщить наружу об ошибке

### Выброс исключений в деструкторе
- Деструкторы по умолчанию noexcept
- Не допускайте выброса исключений в деструкторах объектов
  - Исключение не должно выйти за пределы тела деструктора
- В C++ выброс исключения в деструкторе может приводит к аварийному завершению работы программы, если выброс происходит во время раскрутки стека

### Стремитесь делать move-конструктор и moving оператор присваивания noexcept
- Классы стандартных коллекций используют более эффективные алгоритмы, если у элементов noexcept-конструкторы или операции присваивания
  - Например, vector::push_back будет перемещать элементы, а не копировать, если элементы имеют noexcept move-конструктор

### Бенчмарк
```c++
struct Foo
{
  Foo() = default;
  Foo(std::string data) noexcept
    : data(std::move(data)) {
  }
  Foo(const Foo&) = default;
  Foo& operator=(const Foo&) = default;
  Foo(Foo&& other) noexcept
    : data(std::move(other.data)) {
  }
  Foo& operator=(Foo&& other) noexcept{ 
    data = std::move(other.data);
    return *this; 
  }
  std::string data;
};

struct Bar
{
  Bar() = default;
  Bar(std::string data)
    : data(std::move(data)) {
  }
  Bar(const Bar&) = default;
  Bar& operator=(const Bar&) = default;
  Bar(Bar&& other)
    : data(std::move(other.data)) {
  }
  Bar& operator=(Bar&& other) { 
    data = std::move(other.data);
    return *this; 
  }
  std::string data;
};
```

## Exception-safe programming
Разработка кода, безопасного к возникновению исключений

### Гарантии безопасности исключений
- Отсутствие безопасности исключений
- Базовый уровень безопасности
- Сильный (строгий) уровень безопасности
- Гарантия отсутствия исключений (гарантия бессбойности)

- Каждый следующий уровень предоставляет все гарантии предыдущих уровней

### Отсутствие безопасности исключений
- Если функция выбросит исключение, состояние программы может быть невалидным
- Последствия
  - Undefined Behavior
  - Утечки памяти и других ресурсов
  - Аварийное завершение программы

### Базовый уровень безопасности
- Если функция выбросит исключение, состояние программы остаётся валидным
- Сохраняются инварианты объектов, ресурсы не утекают
- Этот уровень безопасности исключений считается приемлемым
- Вы должны ориентироваться на этот уровень или более высокий

### Сильный (строгий) уровень безопасности
- При выбросе исключений гарантируется
  - Гарантии базового уровня безопасности
  - Отсутствие побочных эффектов (commit-or-rollback)
    - Объекты возвращаются в состояние, в котором они находились до выполнения операции
- Достижение уровня этого безопасности может быть трудоемкой операцией или потребовать изменения архитектуры объекта

### Гарантия отсутствия исключений (гарантия бессбойности)
- При выполнении операции исключения не выбрасываются
- В C++ по умолчанию деструкторы не должны выбрасывать исключений
- Не должен выбрасывать исключений и код, вызываемый извне приложения
  - Callbacks, Event Handlers
  - Вызовы из third party-кода

### Спецификатор noexcept
```c++
class TV
{
public:
  bool IsTurnedOn() const noexcept
  {
    return m_isTurnedOn;
  }
private:
  bool m_isTurnedOn;
};
```

### noexcept move constructor
```c++
class MyString
{
public:
  MyString(MyString&& other) noexcept
    : m_chars(other.m_chars)
    , m_size(other.m_size)
    , m_capacity(other.m_capacity)
  {
    other.m_chars = nullptr;
    other.m_size = m_capacity = 0;
  }
 
private:
  char* m_chars;
  size_t m_size;
  size_t m_capacity;
};
```

### Не-noexcept move constructor
```c++
class Dictionary
{
public:
  Dictionary(Dictionary&& other)
    : m_translations(std::move(other.m_translations))
  {}
private:
  std::unordered_map<std::string, std::string> m_translations;
};

Warning C26439: This kind of function may not throw. Declare it 'noexcept'.
```

### noexcept(false)
```c++
class Dictionary
{
public:
  Dictionary(Dictionary&& other) noexcept(false)
    : m_translations(std::move(other.m_translations))
  {
  }
 
private:
  std::unordered_map<std::string, std::string> m_translations;
};
```

- Функция выполняет загрузку содержимого файла в память и возвращает результат в виде vector<char>
  - Имя файла передается в виде параметра функции
- Проанализировать код функции на предмет безопасности исключений
- При наличии проблем с безопасностью предложить способы их исправления

```c++
vector<char> ReadFileToVector(const char* fileName)
{
	// Открываем
	FILE * pFile = NULL;
	fopen_s(&pFile, fileName, "rb"); // fopen_s - функция на языке C

	// Проверяем успешность
	vector<char> buf;
	if (!pFile) return buf;

	// Ресайзим буфер
	fseek(pFile, 0, SEEK_END);       // fseek – функция на языке C
	buf.resize(ftell(pFile));        // ftell - функция на языке C
	fseek(pFile, 0, SEEK_SET); 

	// Читаем
	fread(buf.data(), 1, buf.size(), pFile); // fread - функция на языке C

	// Выходим и возвращаем результат
	fclose(pFile);                   // fclose - функция на языке C
	return buf;
}
```

### Анализ кода и возможные решения проблем
- Нет возможности отличить ошибку открытия файла от считывания содержимого пустого файла
  - Решение: Бросать исключение при ошибке открытия файла
- При выбросе исключения bad_alloc файл не будет закрыт
  - Возможные решения:
    - Явный перехват исключения с перевыбросом после закрытия
    - BOOST_SCOPE_EXIT/gsl::finally
    - Отказ от FILE* в пользу классов с поддержкой идиомы RAII

```c++
vector<char> ReadFileToVectorTryCatch(char * fileName)
{
	FILE * pFile = NULL;
	fopen_s(&pFile, fileName, "rb");
	if (!pFile) throw runtime_error("Failed to open file");

	vector<char> buf;
	try
	{
		fseek(pFile, 0, SEEK_END);
		buf.resize(ftell(pFile));
		fseek(pFile, 0, SEEK_SET);
		if (buf.size()) fread(&buf[0], 1, buf.size(), pFile);
	}
	catch (bad_alloc const&)
	{
		fclose(pFile);
		throw;
	}

	fclose(pFile);
	return buf;
}
```

```c++
vector<char> ReadFileToVectorScopeExit(char * fileName)
{
	FILE * pFile = NULL;
	fopen_s(&pFile, fileName, "rb");

	if (!pFile) throw runtime_error("Failed to open file");

	BOOST_SCOPE_EXIT_ALL((pFile))
	{
		fclose(pFile);
	};

	vector<char> buf;
	fseek(pFile, 0, SEEK_END);
	buf.resize(ftell(pFile));
	fseek(pFile, 0, SEEK_SET);

	if (buf.size())
		fread(&buf[0], 1, buf.size(), pFile);
	return buf;
}
```

```c++
#include <gsl/gsl_util>

vector<char> ReadFileToVectorScopeExit(char * fileName)
{
	FILE * pFile = NULL;
	fopen_s(&pFile, fileName, "rb");

	if (!pFile) throw runtime_error("Failed to open file");

	auto closeOnExit = gsl::finally([pFile]{
		fclose(pFile);
	});

	vector<char> buf;
	fseek(pFile, 0, SEEK_END);
	buf.resize(ftell(pFile));
	fseek(pFile, 0, SEEK_SET);

	if (buf.size())
		fread(&buf[0], 1, buf.size(), pFile);
	return buf;
}
```

## Идиома RAII (Resource Acquisition Is Initialization)
- Идиома программирования, при которой владение ресурсом привязано к времени жизни объекта
  - Получение ресурса обычно выполняется в момент создания объекта, а освобождение – в момент разрушения
  - Если ресурс получить не удалось, объект не создаётся
- Идиома гарантирует владение ресурсом между окончанием инициализации объекта и началом его разрушением

### Пример – полезная библиотека на языке C
```c++
struct Resource
{
};

Resource* CreateResource();
void UseResource(Resource* resource);
// Удаляет ресурс. Если resource == nullptr, функиция ничего не делает
void DeleteResource(Resource* resource);

class ResourceHolder {
public:
    ResourceHolder() : m_resource{ CreateResource() } {
        if (!m_resource) throw std::runtime_error("Failed to create resource");
    }

    ResourceHolder(const ResourceHolder&) = delete;
    ResourceHolder& operator=(const ResourceHolder&) = delete;
    ~ResourceHolder() { DeleteResource(m_resource); }

    ResourceHolder(ResourceHolder&& other) noexcept
        : m_resource{ std::exchange(other.m_resource, nullptr) } { }

    ResourceHolder& operator=(ResourceHolder&& rhs) noexcept {
        if (this != &rhs) {
            DeleteResource(m_resource);
            m_resource = std::exchange(rhs.m_resource, nullptr);
        }
        return *this;
    }

    void Use() {
        assert(m_resource);
        UseResource(m_resource);
    }
private:
    Resource* m_resource;
};

int main() {
    ResourceHolder r;
    r.Use();
}
```

```c++
vector<char> ReadFileToVector(char * fileName)
{
	// Создаем и настраиваем файл
	ifstream file;
	file.exceptions(ios_base::badbit);
	file.open(fileName, ios_base::binary);

	// Отключаем пропуск пробелов
	file >> noskipws;

	// Копируем файл в массив
	vector<char> buf(istream_iterator<char>(file),
		(istream_iterator<char>()));

	// Возвращаем результат
	return buf;
}

vector<char> ReadFileToVectorFast(char * fileName)
{
	// Открываем файл
	ifstream file;
	file.exceptions(ios_base::badbit | ios_base::failbit);
	file.open(fileName, ios_base::binary);

	// Резервируем память
	file.seekg(0, ios_base::end);
	vector<char> buf(file.tellg());
	file.seekg(0, ios_base::beg);

	// Читаем
	if (buf.size())
		file.read(&buf[0], buf.size());

	// Возвращаем результат
	return buf;
}
```

- Класс CMyString, предназначенный для хранения строк, предоставляющий следующие операции
  - Конструкторы (по умолчанию, копирования, инициализирующий C-style строкой)
  - Деструктор
  - Доступ к массиву символов строки
  - Оператор присваивания
- Проанализировать методы класса на предмет безопасности исключений
- При наличии проблем предложить способы их устранения

```c++
class CMyString
{
	char * m_pChars;
	size_t m_size;
public:
	CMyString():m_pChars(new char[1]), m_size(0)
	{ m_pChars[0] = '\0’; }

	CMyString(const char * str):m_size(strlen(str))
	{
		m_pChars = new char[m_size + 1];
		memcpy(m_pChars, str, m_size + 1);
	}

	CMyString(CMyString const& other)
		:m_size(other.m_size)
		,m_pChars(new char[other.m_size + 1])
	{
		memcpy(m_pChars, other.m_pChars, m_size + 1);
	}

	~CMyString()
	{
		delete [] m_pChars;
	}

	char const * GetStr() const noexcept
	{
		return m_pChars;
	}

	CMyString & operator=(CMyString const& s)
	{
		delete [] m_pChars;
		m_size = s.m_size;
		m_pChars = new char[m_size + 1];
		memcpy(m_pChars, s.m_pChars, m_size + 1);
		return *this;
	}
};
```

### Анализ проблем и пути решения
- Проблемы с оператором =
  - Присваивание строки самой себе приведет к UB
    - Решение: добавить проверку на самоприсваивание
- Выбрасывание исключения в операторе new приведет к:
  - UB при повторном вызове delete [] m_pChars в деструкторе
  - Невозможность использования экземпляра из-за нарушенных инвариантов

```c++
	CMyString & operator=(CMyString const& s)
	{
		// Защита от самоприсваивания
		if (this != &s)
		{
			char * tmp = new char [s.m_size + 1];

			m_size = s.m_size;
			memcpy(tmp, s.m_pChars, m_size + 1);

			delete [] m_pChars;
			m_pChars = tmp;
		}
		return *this;
	}
```

### Более компактный вариант
```c++
CMyString & operator=(CMyString const& s)
{
	// Защита от самоприсваивания
	if (this != &s)
	{
		CMyString tmp(s);

		std::swap(m_pChars, tmp.m_pChars);
		std::swap(m_size, tmp.m_size);
	}
	return *this;
}
```

### Исключения в конструкторе
- Выброс исключения конструктором означает, что объект не был создан
  - Будут вызваны деструкторы сконструированных полей класса
  - Будут вызваны деструкторы базовых классов
  - Деструктор самого класса вызван не будет
- При разработке конструктора необходимо учитывать данные особенности

- В конструкторе объекта выделяется память под 2 массива
- В деструкторе память, занимаемая массивами, освобождается
- Проанализировать код на предмет безопасности исключений
- При наличии проблем предложить решения

```c++
class X : boost::noncopyable
{
public:
	X(size_t numChars, size_t numInts)
		:m_chars(new char [numChars])
		,m_ints(new int [numInts])	
	{
	}
	~X()
	{
		delete [] m_chars;
		delete [] m_ints;
	}
private:
	char * m_chars;
	int * m_ints;
};
```

### Проблемы и их решения
- Утечка памяти при исключении во время
- new int [numInts]
  - Ранее выделенная память new char [numChars] не будет освобождена
- Возможные решения:
  - Перехват исключения c освобождением памяти и дальнейшим перевыбросом исключения
  - Использование контейнеров с поддержкой идиомы RAII вместо обычных массивов

```c++
class X_fixed1 : boost::noncopyable
{
public:
	X_fixed1(size_t numChars, size_t numInts)
		:m_chars(nullptr),m_ints(nullptr)
	{
		try
		{
			m_chars = new char [numChars]; 	m_ints = new int [numInts];
		}
		catch (exception const&)
		{
			delete [] m_chars;	delete [] m_ints;
			throw;
		}
	}
	~X_fixed1()
	{
		delete [] m_chars;	delete [] m_ints;
	}
private:
	char * m_chars;
	int * m_ints;
};
```

```c++
class X_fixed2 : boost::noncopyable
{
public:
	X_fixed2(size_t numChars, size_t numInts)
	try
		:m_chars(nullptr),m_ints(nullptr)
	{
		m_chars = new char[numChars]; m_ints = new int[numInts];
	}
	catch (exception const&)
	{
		delete [] m_chars;	delete [] m_ints;
		throw;
	}
	~X_fixed2()
	{
		delete [] m_chars;	delete [] m_ints;
	}
private:
	char * m_chars;
	int * m_ints;
};
```

```c++
class X_fixed3 : boost::noncopyable
{
public:
	X_fixed3(size_t numChars, size_t numInts)
		:m_chars(numChars)
		,m_ints(numInts)
	{
	}
private:
	vector<char> m_chars;
	vector<int> m_ints;
};
```

### Умные указатели и RAII контейнеры – не панацея
- Использование умных указателей и контейнеров не гарантирует безопасного к возникновению исключений кода
  - Можно добиться гарантии базовой или минимальной безопасности исключений
- Строгая гарантия безопасности исключений может потребовать внесения изменений в архитектуру класса

```c++
template <typename T>
class Stack
{
	// Элемент списка
	struct Item : boost::noncopyable
	{
		Item(T const& v, shared_ptr<Item> const& p)
		:value(v)
		,pNext(p){}

		T value;
		shared_ptr<Item> pNext;
	};

	typedef shared_ptr<Item> ItemPtr;
	ItemPtr m_pTop;
public:
 Stack(const Stack&) = delete;
 Stack& operator=(const Stack&) = delete;
	bool IsEmpty() const noexcept
	{
		return !m_pTop;
	}
	…
	
	…
	// Помещение элемента на вершину стека
	void Push(T const& value)
	{
		m_pTop = make_shared<Item>(value, m_pTop);
	}

	// Извлечение элемента с вершины стека
	T Pop()
	{
		if (IsEmpty())
			throw logic_error("Stack is empty");

		T result		= m_pTop->value;
		m_pTop			= m_pTop->pNext;

		return result;
	}
};

```

#### Анализ проблем и пути решения
- Выброс исключения при возврате копии временной переменной в методе Pop приведет к нарушению семантики Commit-or-Rollback
  - Элемент из списка удалится, хотя вернуть значение не получилось
- Варианты решения:
  - Снятие элемента с вершины с возвратом значения через выходной параметр
    - Требуется предварительно сконструировать объект-приемник
  - Снятие элемента с вершины с возвратом значения через shared_ptr
  - Разделение метода Pop на 2 операции
    - Получение копии элемента, находящейся на вершине стека
    - Снятие элемента с вершины

```c++
template <typename T>
class StackFixed1 : boost::noncopyable
{
	…
	void Pop(T & value)
	{
		if (IsEmpty())
			throw logic_error("Stack is empty");

		value = m_pTop->value;
		m_pTop = m_pTop->pNext;
	}
	…
};

void Test()
{
	StackFixed1<string> stringStack;
	stringStack.Push("Hello");
	string top; stringStack.Pop(top);
	cout << top << endl;
}
```

```c++
template <typename T>
class StackFixed2 : boost::noncopyable
{
	…
	unique_ptr<T> Pop()
	{
		if (IsEmpty())
			throw logic_error("Stack is empty");

		auto pValue = make_unique<T>(m_pTop->value);
		m_pTop = m_pTop->pNext;
		return pValue;
	}
	…
};

void Test()
{
	StackFixed2<string> stringStack;
	stringStack.Push("Hello");
	cout << *stringStack.Pop() << endl;
}
```

#### Имеющиеся проблемы
- В C++ не определен порядок вычисления значений аргументов функций
  - Дополнительные возможности для оптимизации
  - Создание shared_ptr может произойти после создания объектов в куче, например, при вычислении:
    - `new X`
    - `new Y`
    - `shared_ptr<X>`
    - `shared_ptr<Y>`
  - При выбросе исключения во время new Y память, выделенная в new X, освобождена не будет

#### Возможные решения
- Решение 1: Создать временные переменные типа shared_ptr и передать их в виде аргументов
  - `shared_ptr<X> x(new X);`
  - `shared_ptr<Y> y(new Y);`
  - `DoSomething(x, y);`
  - Недостаток: лишние переменные
- Решение 2: использовать функцию make_shared
  - `DoSomething(make_shared<X>(), make_shared<Y>());`
  - Достоинства:
    - Меньше кода
      - Выше быстродействие (память в куче выделяется один раз сразу для хранения как самого объекта, так и счетчика)
  - Недостаток:
    - Т.к. объект хранится вместе со счетчиком, он будет занимать память (будучи уже разрушен), пока существуют weak-ссылки


### Как сделать класс безопасным к возникновению исключений
- Внутри каждого метода выделить фрагменты, которые могут выбросить исключение
  - Оценить последствия исключений
- Реорганизовать код функции или метода так, чтобы исключения не выбрасывались в процессе изменения состояния объекта (программы)
- После выполнения подготовительных операций можно изменить состояние, используя операции, не выбрасывающие исключений

### Общие рекомендации по разработке Exception-Safe кода
- Стремиться к сокращению размеров методов/функций
  - Один метод – одна задача
- Использовать надежные механизмы
  - RAII, Smart Pointers, надежные библиотеки
- В unit-тестах моделировать наиболее вероятные проблемные ситуации
  - Mock-объекты, бросающие исключения
  - Симуляция ошибок, некорректные входные данные
- Использование вспомогательных инструментов
  - Статический и динамический анализ кода
  - Детекторы утечек памяти















