# Обработка исключений

# Исключения в C++: полное руководство

## 1. Выбрасывание исключения

В C++ исключения выбрасываются с помощью ключевого слова `throw`. Можно выбрасывать объекты любого типа, но рекомендуется использовать классы, унаследованные от `std::exception`.

```cpp
void processFile(const std::string& filename) {
    if (filename.empty()) {
        throw std::invalid_argument("Filename cannot be empty");
    }
    // Обработка файла...
}
```

**Особенности:**
- При выбросе исключения выполнение текущей функции немедленно прекращается
- Стек вызовов начинает раскручиваться до первого подходящего обработчика `catch`
- Можно бросать как примитивные типы (`throw 42;`), так и сложные объекты

## 2. Перехват исключений заданного типа

Для перехвата исключений используется блок `try-catch`:

```cpp
try {
    processFile("");
} 
catch (const std::invalid_argument& e) {
    std::cerr << "Invalid argument: " << e.what() << std::endl;
}
```

**Особенности:**
- Обработчики проверяются по порядку сверху вниз
- Первый подходящий обработчик выполняется, остальные игнорируются
- Лучше ловить исключения по константной ссылке (`const &`)

## 3. Перехват всех исключений

Можно перехватывать все исключения с помощью `catch (...)`:

```cpp
try {
    riskyOperation();
} 
catch (...) {
    std::cerr << "Unknown exception occurred" << std::endl;
}
```

**Важно:**
- Такой обработчик должен идти последним
- Внутри него нельзя получить информацию об исключении
- В C++11 можно использовать `std::current_exception()` для получения исключения

## 4. Перевыброс пойманного исключения

Для перевыброса используется `throw` без аргументов:

```cpp
try {
    processFile("invalid.txt");
} 
catch (const std::exception& e) {
    logError(e.what());
    throw;  // Перевыбрасываем то же исключение
}
```

**Отличие от `throw e;`:**
- `throw;` сохраняет оригинальный тип и стек вызовов
- `throw e;` создает копию исключения, теряя информацию о производном типе

## 5. Особенности исключений в конструкторах и деструкторах

### Конструкторы:
- Если исключение выбрасывается в конструкторе, деструктор не вызывается
- Уже созданные подобъекты уничтожаются в обратном порядке
- Рекомендуется использовать RAII для управления ресурсами

```cpp
class ResourceHolder {
    int* resource;
public:
    ResourceHolder() : resource(new int[100]) {
        if (someCondition) {
            throw std::runtime_error("Construction failed");
            // delete[] resource НЕ вызывается!
        }
    }
    ~ResourceHolder() { delete[] resource; }
};
```

### Деструкторы:
- Деструкторы по умолчанию `noexcept` (C++11)
- Исключение в деструкторе приводит к вызову `std::terminate`
- Используйте `try-catch` внутри деструктора для обработки ошибок

## 6. Указание, что функция не выбрасывает исключений

В C++11+ есть два способа:

```cpp
// Способ 1 (C++11)
void safeFunction() noexcept {
    // Гарантировано не бросает исключений
}

// Способ 2 (C++20)
void anotherSafeFunction() noexcept(true) {
    // То же самое
}
```

**Преимущества:**
- Позволяет компилятору лучше оптимизировать код
- Если исключение все же выброшено, вызывается `std::terminate`

## 7. Почему перемещающие операции должны быть noexcept

1. **Производительность**: `std::vector` и другие контейнеры используют перемещение вместо копирования только если оно `noexcept`
2. **Безопасность**: гарантирует, что операция не прервется посередине
3. **Совместимость**: многие алгоритмы STL требуют `noexcept` перемещения

```cpp
class Movable {
    int* data;
public:
    // Перемещающий конструктор
    Movable(Movable&& other) noexcept : data(other.data) {
        other.data = nullptr;
    }
    
    // Перемещающее присваивание
    Movable& operator=(Movable&& other) noexcept {
        delete data;
        data = other.data;
        other.data = nullptr;
        return *this;
    }
};
```

## 8. Проблема срезки (slicing) при исключениях

**Срезка** происходит, когда исключение производного класса ловится по значению базового класса:

```cpp
try {
    throw Derived();
} 
catch (Base e) {  // Срезка! Теряем часть объекта
    // Обрабатываем только Base часть
}
```

**Решение** - ловить по ссылке:

```cpp
catch (const Base& e) {  // Без срезки
    // Полный доступ к объекту
}
```

## 9. Стандартные классы исключений

Базовый класс - `std::exception`. Основные стандартные исключения:

- `std::logic_error` (ошибки логики программы):
    - `std::invalid_argument`
    - `std::domain_error`
    - `std::length_error`
    - `std::out_of_range`

- `std::runtime_error` (ошибки времени выполнения):
    - `std::range_error`
    - `std::overflow_error`
    - `std::underflow_error`
    - `std::system_error`

## 10. Иерархия классов исключений

```
std::exception
├── std::logic_error
│   ├── std::invalid_argument
│   ├── std::domain_error
│   ├── std::length_error
│   └── std::out_of_range
├── std::runtime_error
│   ├── std::range_error
│   ├── std::overflow_error
│   ├── std::underflow_error
│   └── std::system_error
└── другие...
```

## 11. Преимущества классов как исключений

1. **Иерархия** - можно ловить базовые классы
2. **Информативность** - метод `what()` возвращает описание
3. **Безопасность типов** - в отличие примитивных типов
4. **Расширяемость** - можно добавлять свои поля и методы

## 12. Проверка на noexcept

В C++11 появились traits для проверки:

```cpp
#include <type_traits>

static_assert(std::is_nothrow_move_constructible<MyClass>::value,
              "MyClass should have noexcept move constructor");
```

Также можно использовать `noexcept(expression)`:

```cpp
bool moveIsNoexcept = noexcept(MyClass(std::declval<MyClass&&>()));
```

## 13. std::nested_exception

Позволяет создавать цепочки исключений:

```cpp
void handle() {
    try {
        someOperation();
    }
    catch (...) {
        std::throw_with_nested(std::runtime_error("Operation failed"));
    }
}

void printException(const std::exception& e, int level = 0) {
    std::cerr << std::string(level, ' ') << e.what() << '\n';
    try {
        std::rethrow_if_nested(e);
    }
    catch (const std::exception& nested) {
        printException(nested, level + 1);
    }
}
```

## 14. Перехват всех исключений стандартной библиотеки

Для перехвата всех стандартных исключений:

```cpp
try {
    // Код, использующий STL
} 
catch (const std::exception& e) {
    // Ловим все, что наследуется от std::exception
    std::cerr << "STL exception: " << e.what() << std::endl;
} 
catch (...) {
    // Ловим все остальное
    std::cerr << "Unknown exception" << std::endl;
}
```

**Рекомендации:**
- Всегда наследуйте свои исключения от `std::exception`
- Используйте `what()` для получения сообщения об ошибке
- Ловите исключения по константной ссылке